Traceback (most recent call last):
  File "/home/work/dashboard/back/wangshuai14/insertmac.py", line 21, in <module>
    fin = open(infile)
IOError: [Errno 2] No such file or directory: '/home/work/data_unused_machine/data/10/hz.machine.available.ATLEAST_1_RUNNING'
Traceback (most recent call last):
  File "/home/work/dashboard/back/wangshuai14/insertmac.py", line 21, in <module>
    fin = open(infile)
IOError: [Errno 2] No such file or directory: '/home/work/data_unused_machine/data/10/hz.machine.available.ATLEAST_1_RUNNING'
Traceback (most recent call last):
  File "/home/work/dashboard/back/wangshuai14/insertmac.py", line 22, in <module>
    fin = open(infile)
IOError: [Errno 2] No such file or directory: '/home/work/data_unused_machine/data/analyse_machine_userate/2015-08-11/10/bj.machine.available.ATLEAST_1_RUNNING'
Traceback (most recent call last):
  File "/home/work/dashboard/back/wangshuai14/insertmac.py", line 90, in <module>
    fin = open(infile)
IOError: [Errno 2] No such file or directory: '/home/work/data_unused_machine/data/analyse_machine_userate/2015-08-12/01/bj.machine.available.NO_RUNNING.NOTinerr.ONLY_HAS_STOP_INSTANCE'
Traceback (most recent call last):
  File "/home/work/dashboard/back/wangshuai14/insertmac.py", line 22, in <module>
    fin = open(infile)
IOError: [Errno 2] No such file or directory: '/home/work/data_unused_machine/data/analyse_machine_userate/2015-08-12/18/hz.machine.available.ATLEAST_1_RUNNING'
